{
  "schematic_name": "leaning_tower_of_pisa",
  "blocks": [
    { "block_type": "smooth_sandstone", "x": 0, "y": 0, "z": 0 },
    { "block_type": "smooth_sandstone", "x": 1, "y": 0, "z": 0 },
    { "block_type": "smooth_sandstone", "x": 2, "y": 0, "z": 0 },
    { "block_type": "smooth_sandstone", "x": 3, "y": 0, "z": 0 },
    { "block_type": "smooth_sandstone", "x": 4, "y": 0, "z": 0 },
    { "block_type": "smooth_sandstone", "x": 5, "y": 0, "z": 0 },
    { "block_type": "smooth_sandstone", "x": 6, "y": 0, "z": 0 },
    { "block_type": "smooth_sandstone", "x": 7, "y": 0, "z": 0 },
    { "block_type": "smooth_sandstone", "x": 0, "y": 0, "z": 1 },
    { "block_type": "smooth_sandstone", "x": 7, "y": 0, "z": 1 },
    { "block_type": "smooth_sandstone", "x": 0, "y": 0, "z": 2 },
    { "block_type": "smooth_sandstone", "x": 7, "y": 0, "z": 2 },
    { "block_type": "smooth_sandstone", "x": 0, "y": 0, "z": 3 },
    { "block_type": "smooth_sandstone", "x": 7, "y": 0, "z": 3 },
    { "block_type": "smooth_sandstone", "x": 0, "y": 0, "z": 4 },
    { "block_type": "smooth_sandstone", "x": 7, "y": 0, "z": 4 },
    { "block_type": "smooth_sandstone", "x": 0, "y": 0, "z": 5 },
    { "block_type": "smooth_sandstone", "x": 7, "y": 0, "z": 5 },
    { "block_type": "smooth_sandstone", "x": 0, "y": 0, "z": 6 },
    { "block_type": "smooth_sandstone", "x": 7, "y": 0, "z": 6 },
    { "block_type": "smooth_sandstone", "x": 0, "y": 0, "z": 7 },
    { "block_type": "smooth_sandstone", "x": 1, "y": 0, "z": 7 },
    { "block_type": "smooth_sandstone", "x": 2, "y": 0, "z": 7 },
    { "block_type": "smooth_sandstone", "x": 3, "y": 0, "z": 7 },
    { "block_type": "smooth_sandstone", "x": 4, "y": 0, "z": 7 },
    { "block_type": "smooth_sandstone", "x": 5, "y": 0, "z": 7 },
    { "block_type": "smooth_sandstone", "x": 6, "y": 0, "z": 7 },
    { "block_type": "smooth_sandstone", "x": 7, "y": 0, "z": 7 },
    { "block_type": "chiseled_sandstone", "x": 1, "y": 1, "z": 1 },
    { "block_type": "chiseled_sandstone", "x": 2, "y": 1, "z": 1 },
    { "block_type": "chiseled_sandstone", "x": 3, "y": 1, "z": 1 },
    { "block_type": "chiseled_sandstone", "x": 4, "y": 1, "z": 1 },
    { "block_type": "chiseled_sandstone", "x": 5, "y": 1, "z": 1 },
    { "block_type": "chiseled_sandstone", "x": 6, "y": 1, "z": 1 },
    { "block_type": "chiseled_sandstone", "x": 1, "y": 1, "z": 6 },
    { "block_type": "chiseled_sandstone", "x": 2, "y": 1, "z": 6 },
    { "block_type": "chiseled_sandstone", "x": 3, "y": 1, "z": 6 },
    { "block_type": "chiseled_sandstone", "x": 4, "y": 1, "z": 6 },
    { "block_type": "chiseled_sandstone", "x": 5, "y": 1, "z": 6 },
    { "block_type": "chiseled_sandstone", "x": 6, "y": 1, "z": 6 },
    { "block_type": "chiseled_sandstone", "x": 1, "y": 1, "z": 2 },
    { "block_type": "chiseled_sandstone", "x": 6, "y": 1, "z": 2 },
    { "block_type": "chiseled_sandstone", "x": 1, "y": 1, "z": 3 },
    { "block_type": "chiseled_sandstone", "x": 6, "y": 1, "z": 3 },
    { "block_type": "chiseled_sandstone", "x": 1, "y": 1, "z": 4 },
    { "block_type": "chiseled_sandstone", "x": 6, "y": 1, "z": 4 },
    { "block_type": "chiseled_sandstone", "x": 1, "y": 1, "z": 5 },
    { "block_type": "chiseled_sandstone", "x": 6, "y": 1, "z": 5 },
    { "block_type": "chiseled_sandstone", "x": 1, "y": 2, "z": 1 },
    { "block_type": "chiseled_sandstone", "x": 2, "y": 2, "z": 1 },
    { "block_type": "chiseled_sandstone", "x": 3, "y": 2, "z": 1 },
    { "block_type": "chiseled_sandstone", "x": 4, "y": 2, "z": 1 },
    { "block_type": "chiseled_sandstone", "x": 5, "y": 2, "z": 1 },
    { "block_type": "chiseled_sandstone", "x": 6, "y": 2, "z": 1 },
    { "block_type": "chiseled_sandstone", "x": 1, "y": 2, "z": 6 },
    { "block_type": "chiseled_sandstone", "x": 2, "y": 2, "z": 6 },
    { "block_type": "chiseled_sandstone", "x": 3, "y": 2, "z": 6 },
    { "block_type": "chiseled_sandstone", "x": 4, "y": 2, "z": 6 },
    { "block_type": "chiseled_sandstone", "x": 5, "y": 2, "z": 6 },
    { "block_type": "chiseled_sandstone", "x": 6, "y": 2, "z": 6 },
    { "block_type": "chiseled_sandstone", "x": 1, "y": 2, "z": 2 },
    { "block_type": "chiseled_sandstone", "x": 6, "y": 2, "z": 2 },
    { "block_type": "chiseled_sandstone", "x": 1, "y": 2, "z": 3 },
    { "block_type": "chiseled_sandstone", "x": 6, "y": 2, "z": 3 },
    { "block_type": "chiseled_sandstone", "x": 1, "y": 2, "z": 4 },
    { "block_type": "chiseled_sandstone", "x": 6, "y": 2, "z": 4 },
    { "block_type": "chiseled_sandstone", "x": 1, "y": 2, "z": 5 },
    { "block_type": "chiseled_sandstone", "x": 6, "y": 2, "z": 5 },
    { "block_type": "smooth_sandstone", "x": 1, "y": 3, "z": 1 },
    { "block_type": "smooth_sandstone", "x": 2, "y": 3, "z": 1 },
    { "block_type": "smooth_sandstone", "x": 3, "y": 3, "z": 1 },
    { "block_type": "smooth_sandstone", "x": 4, "y": 3, "z": 1 },
    { "block_type": "smooth_sandstone", "x": 5, "y": 3, "z": 1 },
    { "block_type": "smooth_sandstone", "x": 6, "y": 3, "z": 1 },
    { "block_type": "smooth_sandstone", "x": 1, "y": 3, "z": 6 },
    { "block_type": "smooth_sandstone", "x": 2, "y": 3, "z": 6 },
    { "block_type": "smooth_sandstone", "x": 3, "y": 3, "z": 6 },
    { "block_type": "smooth_sandstone", "x": 4, "y": 3, "z": 6 },
    { "block_type": "smooth_sandstone", "x": 5, "y": 3, "z": 6 },
    { "block_type": "smooth_sandstone", "x": 6, "y": 3, "z": 6 },
    { "block_type": "smooth_sandstone", "x": 1, "y": 3, "z": 2 },
    { "block_type": "smooth_sandstone", "x": 6, "y": 3, "z": 2 },
    { "block_type": "smooth_sandstone", "x": 1, "y": 3, "z": 3 },
    { "block_type": "smooth_sandstone", "x": 6, "y": 3, "z": 3 },
    { "block_type": "smooth_sandstone", "x": 1, "y": 3, "z": 4 },
    { "block_type": "smooth_sandstone", "x": 6, "y": 3, "z": 4 },
    { "block_type": "smooth_sandstone", "x": 1, "y": 3, "z": 5 },
    { "block_type": "smooth_sandstone", "x": 6, "y": 3, "z": 5 }
  ]
}
