{
  "schematic_name": "leaning_tower_of_pisa",
  "blocks": [
    { "block_type": "smooth_stone", "x": 5, "y": 0, "z": 5 },
    { "block_type": "smooth_stone", "x": 6, "y": 0, "z": 5 },
    { "block_type": "smooth_stone", "x": 7, "y": 0, "z": 5 },
    { "block_type": "smooth_stone", "x": 8, "y": 0, "z": 5 },
    { "block_type": "smooth_stone", "x": 9, "y": 0, "z": 5 },
    { "block_type": "smooth_stone", "x": 10, "y": 0, "z": 5 },
    { "block_type": "smooth_stone", "x": 5, "y": 0, "z": 6 },
    { "block_type": "smooth_stone", "x": 10, "y": 0, "z": 6 },
    { "block_type": "smooth_stone", "x": 5, "y": 0, "z": 7 },
    { "block_type": "smooth_stone", "x": 10, "y": 0, "z": 7 },
    { "block_type": "smooth_stone", "x": 5, "y": 0, "z": 8 },
    { "block_type": "smooth_stone", "x": 10, "y": 0, "z": 8 },
    { "block_type": "smooth_stone", "x": 5, "y": 0, "z": 9 },
    { "block_type": "smooth_stone", "x": 10, "y": 0, "z": 9 },
    { "block_type": "smooth_stone", "x": 5, "y": 0, "z": 10 },
    { "block_type": "smooth_stone", "x": 6, "y": 0, "z": 10 },
    { "block_type": "smooth_stone", "x": 7, "y": 0, "z": 10 },
    { "block_type": "smooth_stone", "x": 8, "y": 0, "z": 10 },
    { "block_type": "smooth_stone", "x": 9, "y": 0, "z": 10 },
    { "block_type": "smooth_stone", "x": 10, "y": 0, "z": 10 },
    { "block_type": "quartz_pillar", "x": 5, "y": 1, "z": 5 },
    { "block_type": "chiseled_quartz_block", "x": 6, "y": 1, "z": 5 },
    { "block_type": "chiseled_quartz_block", "x": 7, "y": 1, "z": 5 },
    { "block_type": "chiseled_quartz_block", "x": 8, "y": 1, "z": 5 },
    { "block_type": "chiseled_quartz_block", "x": 9, "y": 1, "z": 5 },
    { "block_type": "quartz_pillar", "x": 10, "y": 1, "z": 5 },
    { "block_type": "chiseled_quartz_block", "x": 5, "y": 1, "z": 6 },
    { "block_type": "chiseled_quartz_block", "x": 10, "y": 1, "z": 6 },
    { "block_type": "chiseled_quartz_block", "x": 5, "y": 1, "z": 7 },
    { "block_type": "chiseled_quartz_block", "x": 10, "y": 1, "z": 7 },
    { "block_type": "chiseled_quartz_block", "x": 5, "y": 1, "z": 8 },
    { "block_type": "chiseled_quartz_block", "x": 10, "y": 1, "z": 8 },
    { "block_type": "chiseled_quartz_block", "x": 5, "y": 1, "z": 9 },
    { "block_type": "chiseled_quartz_block", "x": 10, "y": 1, "z": 9 },
    { "block_type": "quartz_pillar", "x": 5, "y": 1, "z": 10 },
    { "block_type": "chiseled_quartz_block", "x": 6, "y": 1, "z": 10 },
    { "block_type": "chiseled_quartz_block", "x": 7, "y": 1, "z": 10 },
    { "block_type": "chiseled_quartz_block", "x": 8, "y": 1, "z": 10 },
    { "block_type": "chiseled_quartz_block", "x": 9, "y": 1, "z": 10 },
    { "block_type": "quartz_pillar", "x": 10, "y": 1, "z": 10 },
    { "block_type": "quartz_pillar", "x": 5, "y": 2, "z": 5 },
    { "block_type": "quartz_pillar", "x": 10, "y": 2, "z": 5 },
    { "block_type": "quartz_pillar", "x": 5, "y": 2, "z": 10 },
    { "block_type": "quartz_pillar", "x": 10, "y": 2, "z": 10 },
    { "block_type": "quartz_pillar", "x": 5, "y": 3, "z": 5 },
    { "block_type": "quartz_pillar", "x": 10, "y": 3, "z": 5 },
    { "block_type": "quartz_pillar", "x": 5, "y": 3, "z": 10 },
    { "block_type": "quartz_pillar", "x": 10, "y": 3, "z": 10 },
    { "block_type": "quartz_pillar", "x": 5, "y": 4, "z": 5 },
    { "block_type": "quartz_pillar", "x": 10, "y": 4, "z": 5 },
    { "block_type": "quartz_pillar", "x": 5, "y": 4, "z": 10 },
    { "block_type": "quartz_pillar", "x": 10, "y": 4, "z": 10 },
    { "block_type": "smooth_quartz", "x": 5, "y": 5, "z": 5 },
    { "block_type": "smooth_quartz", "x": 6, "y": 5, "z": 5 },
    { "block_type": "smooth_quartz", "x": 7, "y": 5, "z": 5 },
    { "block_type": "smooth_quartz", "x": 8, "y": 5, "z": 5 },
    { "block_type": "smooth_quartz", "x": 9, "y": 5, "z": 5 },
    { "block_type": "smooth_quartz", "x": 10, "y": 5, "z": 5 },
    { "block_type": "smooth_quartz", "x": 5, "y": 5, "z": 6 },
    { "block_type": "smooth_quartz", "x": 10, "y": 5, "z": 6 },
    { "block_type": "smooth_quartz", "x": 5, "y": 5, "z": 7 }
  ]
}
